<sdf version="1.7">
  <model name="model">
    <link name="body">
      <inertial>
        <pose>0.000140893756 -3.81281063e-12 0.0222411843 0 0 0</pose>
        <mass>0.0546196678</mass>
        <inertia>
          <ixx>4.00054126e-05</ixx>
          <ixy>4.42605896e-14</ixy>
          <ixz>7.7537018e-08</ixz>
          <iyy>5.1950393e-05</iyy>
          <iyz>6.90946541e-16</iyz>
          <izz>6.41572432e-05</izz>
        </inertia>
      </inertial>
      <visual name="body_visual">
        <geometry>
          <mesh>
            <uri>meshes/body.stl</uri>
            <scale>0.001 0.001 0.001</scale>
          </mesh>
        </geometry>
      </visual>
      <collision name="body_collision">
        <geometry>
          <mesh>
            <uri>meshes/body_collision.stl</uri>
            <scale>0.001 0.001 0.001</scale>
          </mesh>
        </geometry>
      </collision>
    </link>
    <link name="arm_l">
      <inertial>
        <pose>0.0111812127 0.0401484551 0.026 0 0 0</pose>
        <mass>0.00364086718</mass>
        <inertia>
          <ixx>7.95204366e-08</ixx>
          <ixy>-1.60987397e-08</ixy>
          <ixz>4.33064997e-22</ixz>
          <iyy>3.45914757e-07</iyy>
          <iyz>5.77419996e-22</iyz>
          <izz>3.28699215e-07</izz>
        </inertia>
      </inertial>
      <visual name="arm_l_visual">
        <geometry>
          <mesh>
            <uri>meshes/arm_l.stl</uri>
            <scale>0.001 0.001 0.001</scale>
          </mesh>
        </geometry>
      </visual>
      <collision name="arm_l_collision">
        <geometry>
          <mesh>
            <uri>meshes/arm_l_collision.stl</uri>
            <scale>0.001 0.001 0.001</scale>
          </mesh>
        </geometry>
      </collision>
    </link>
    <link name="arm_r">
      <inertial>
        <pose>0.0248187873 -0.0401484551 0.026 0 0 0</pose>
        <mass>0.00364086715</mass>
        <inertia>
          <ixx>7.95204358e-08</ixx>
          <ixy>-1.60987391e-08</ixy>
          <ixz>-1.44354999e-21</ixz>
          <iyy>3.45914748e-07</iyy>
          <iyz>1.15483999e-21</iyz>
          <izz>3.28699206e-07</izz>
        </inertia>
      </inertial>
      <visual name="arm_r_visual">
        <geometry>
          <mesh>
            <uri>meshes/arm_r.stl</uri>
            <scale>0.001 0.001 0.001</scale>
          </mesh>
        </geometry>
      </visual>
      <collision name="arm_r_collision">
        <geometry>
          <mesh>
            <uri>meshes/arm_r_collision.stl</uri>
            <scale>0.001 0.001 0.001</scale>
          </mesh>
        </geometry>
      </collision>
    </link>
    <link name="head">
      <inertial>
        <pose>9.00477979e-06 1.62905618e-14 0.0571533131 0 0 0</pose>
        <mass>0.0188317912</mass>
        <inertia>
          <ixx>1.89734192e-06</ixx>
          <ixy>6.60643229e-18</ixy>
          <ixz>2.75539504e-10</ixz>
          <iyy>1.89369465e-06</iyy>
          <iyz>1.51377629e-19</iyz>
          <izz>2.79788128e-06</izz>
        </inertia>
      </inertial>
      <visual name="head_visual">
        <geometry>
          <mesh>
            <uri>meshes/head.stl</uri>
            <scale>0.001 0.001 0.001</scale>
          </mesh>
        </geometry>
      </visual>
      <collision name="head_collision">
        <geometry>
          <mesh>
            <uri>meshes/head_collision.stl</uri>
            <scale>0.001 0.001 0.001</scale>
          </mesh>
        </geometry>
      </collision>
    </link>
    <link name="pcb">
      <inertial>
        <pose>0.00837585779 0 0.00997300979 0 0 0</pose>
        <mass>0.00793897658</mass>
        <inertia>
          <ixx>1.00081154e-06</ixx>
          <ixy>-0</ixy>
          <ixz>-2.0128195e-07</ixz>
          <iyy>1.64556149e-06</iyy>
          <iyz>-7.21774995e-24</iyz>
          <izz>2.46668842e-06</izz>
        </inertia>
      </inertial>
      <visual name="pcb_visual">
        <geometry>
          <mesh>
            <uri>meshes/pcb.stl</uri>
            <scale>0.001 0.001 0.001</scale>
          </mesh>
        </geometry>
      </visual>
      <collision name="pcb_collision">
        <geometry>
          <mesh>
            <uri>meshes/pcb_collision.stl</uri>
            <scale>0.001 0.001 0.001</scale>
          </mesh>
        </geometry>
      </collision>
    </link>
    <link name="servo_l">
      <inertial>
        <pose>-0.0203803824 0.0120000002 0.0215341921 0 0 0</pose>
        <mass>0.00878229194</mass>
        <inertia>
          <ixx>5.59007982e-07</ixx>
          <ixy>-6.99479366e-16</ixy>
          <ixz>4.19450663e-08</ixz>
          <iyy>8.79547159e-07</iyy>
          <iyz>1.68561196e-15</iyz>
          <izz>5.3350799e-07</izz>
        </inertia>
      </inertial>
      <visual name="servo_l_visual">
        <geometry>
          <mesh>
            <uri>meshes/servo_l.stl</uri>
            <scale>0.001 0.001 0.001</scale>
          </mesh>
        </geometry>
      </visual>
      <collision name="servo_l_collision">
        <geometry>
          <mesh>
            <uri>meshes/servo_l_collision.stl</uri>
            <scale>0.001 0.001 0.001</scale>
          </mesh>
        </geometry>
      </collision>
    </link>
    <link name="servo_r">
      <inertial>
        <pose>-0.0203803824 -0.0120000002 0.0215341921 0 0 0</pose>
        <mass>0.00878229194</mass>
        <inertia>
          <ixx>5.59007982e-07</ixx>
          <ixy>6.99479366e-16</ixy>
          <ixz>4.19450663e-08</ixz>
          <iyy>8.79547159e-07</iyy>
          <iyz>-1.68561167e-15</iyz>
          <izz>5.3350799e-07</izz>
        </inertia>
      </inertial>
      <visual name="servo_r_visual">
        <geometry>
          <mesh>
            <uri>meshes/servo_r.stl</uri>
            <scale>0.001 0.001 0.001</scale>
          </mesh>
        </geometry>
      </visual>
      <collision name="servo_r_collision">
        <geometry>
          <mesh>
            <uri>meshes/servo_r_collision.stl</uri>
            <scale>0.001 0.001 0.001</scale>
          </mesh>
        </geometry>
      </collision>
    </link>
    <joint name="arm_l_pitch" type="revolute">
      <parent>body</parent>
      <child>arm_l</child>
      <pose>0.018 0.037 0.026 0 0 0</pose>
      <axis>
        <xyz>0 1 0</xyz>
        <limit>
          <lower>-0.698131701</lower>
          <upper>1.74532925</upper>
        </limit>
      </axis>
    </joint>
    <joint name="arm_r_pitch" type="revolute">
      <parent>body</parent>
      <child>arm_r</child>
      <pose>0.018 -0.037 0.026 0 0 0</pose>
      <axis>
        <xyz>0 1 0</xyz>
        <limit>
          <lower>-0.698131701</lower>
          <upper>1.74532925</upper>
        </limit>
      </axis>
    </joint>
    <joint name="head_pan" type="revolute">
      <parent>body</parent>
      <child>head</child>
      <pose>0 0 0.046 0 0 0</pose>
      <axis>
        <xyz>0 0 1</xyz>
        <limit>
          <lower>-2.0943951</lower>
          <upper>2.0943951</upper>
        </limit>
      </axis>
    </joint>
    <joint name="body_to_pcb" type="fixed">
      <parent>body</parent>
      <child>pcb</child>
      <pose>0 0 0 0 0 0</pose>
    </joint>
    <joint name="body_to_servo_l" type="fixed">
      <parent>body</parent>
      <child>servo_l</child>
      <pose>0 0 0 0 0 0</pose>
    </joint>
    <joint name="body_to_servo_r" type="fixed">
      <parent>body</parent>
      <child>servo_r</child>
      <pose>0 0 0 0 0 0</pose>
    </joint>
  </model>
</sdf>